Workbook
Name Nums: Data!$A$2:$A$11
Name Rate: 0.05

Sheet Legacy
A1: operators: 1+2*3 | B1: =1+2*3 -> 7
A2: operators: -2^2 | B2: =-2^2 -> 4
A3: operators: 2^-1 | B3: =2^-1 -> 0.5
A4: operators: 10% | B4: =10% -> 0.1
A5: operators: (1+2)% | B5: =(1+2)% -> 0.03
A6: operators: "3"*"4" | B6: ="3"*"4" -> 12
A7: operators: 1+"2" | B7: =1+"2" -> 3
A8: operators: "a"&1&TRUE | B8: ="a"&1&TRUE -> a1TRUE
A9: operators: TRUE+1 | B9: =TRUE+1 -> 2
A10: operators: "10%"*2 | B10: ="10%"*2 -> 0.2
A11: operators: 1=1.0 | B11: =1=1 -> TRUE
A12: operators: "A"="a" | B12: ="A"="a" -> TRUE
A13: operators: 1<"a" | B13: =1<"a" -> TRUE
A14: operators: TRUE>1 | B14: =TRUE>1 -> TRUE
A15: operators: "b">"A" | B15: ="b">"A" -> TRUE
A16: operators: Data!C5="" | B16: =Data!C5="" -> TRUE
A17: operators: Data!C5=0 | B17: =Data!C5=0 -> TRUE
A18: operators: Data!C5+1 | B18: =Data!C5+1 -> 1
A19: operators: "1/15/2024"+0 | B19: ="1/15/2024"+0 -> 45306
A20: operators: "2024-01-15"+1 | B20: ="2024-01-15"+1 -> 45307
A21: operators: 0.1+0.2=0.3 | B21: =0.1+0.2=0.3 -> TRUE
A22: operators: 9E+307*10 | B22: =9E+307*10 -> #NUM!
A23: operators: 1/0 | B23: =1/0 -> #DIV/0!
A24: operators: Data!C2+Data!C3 | B24: =Data!C2+Data!C3 -> 3
A25: operators: Data!C2+Data!C7 | B25: =Data!C2+Data!C7 -> #VALUE!
A26: operators: "x"+1 | B26: ="x"+1 -> #VALUE!
A27: operators: 2^0.5 | B27: =2^0.5 -> 1.4142136
A28: operators: Data!A2:A3*2 | B28: =Data!A2:A3*2 -> #VALUE!
A29: math: SUM(Data!A2:A11) | B29: =SUM(Data!A2:A11) -> 55
A30: math: SUM(Data!C2:C11) | B30: =SUM(Data!C2:C11) -> 7.5
A31: math: SUM("2",3,TRUE) | B31: =SUM("2",3,TRUE) -> 6
A32: math: SUM(Data!A2:A11,100) | B32: =SUM(Data!A2:A11,100) -> 155
A33: math: SUM(Data!A:A) | B33: =SUM(Data!A:A) -> 55
A34: math: SUM(Nums) | B34: =SUM(Nums) -> 55
A35: math: SUM(Data!A2:B11) | B35: =SUM(Data!A2:B11) -> 55
A36: math: ROUND(2.345,2) | B36: =ROUND(2.345,2) -> 2.35
A37: math: ROUND(-2.5,0) | B37: =ROUND(-2.5,0) -> -3
A38: math: ROUND(1234.5,-2) | B38: =ROUND(1234.5,-2) -> 1200
A39: math: ROUNDUP(2.341,2) | B39: =ROUNDUP(2.341,2) -> 2.35
A40: math: ROUNDDOWN(-2.349,2) | B40: =ROUNDDOWN(-2.349,2) -> -2.34
...

Sheet Dynamic
A1: operators: 1+2*3 | B1: =1+2*3 -> 7
A13: operators: -2^2 | B13: =-2^2 -> 4
A25: operators: 2^-1 | B25: =2^-1 -> 0.5
A37: operators: 10% | B37: =10% -> 0.1
A49: operators: (1+2)% | B49: =(1+2)% -> 0.03
A61: operators: "3"*"4" | B61: ="3"*"4" -> 12
A73: operators: 1+"2" | B73: =1+"2" -> 3
A85: operators: "a"&1&TRUE | B85: ="a"&1&TRUE -> a1TRUE
A97: operators: TRUE+1 | B97: =TRUE+1 -> 2
A109: operators: "10%"*2 | B109: ="10%"*2 -> 0.2
A121: operators: 1=1.0 | B121: =1=1 -> TRUE
A133: operators: "A"="a" | B133: ="A"="a" -> TRUE
A145: operators: 1<"a" | B145: =1<"a" -> TRUE
A157: operators: TRUE>1 | B157: =TRUE>1 -> TRUE
A169: operators: "b">"A" | B169: ="b">"A" -> TRUE
A181: operators: Data!C5="" | B181: =Data!C5="" -> TRUE
A193: operators: Data!C5=0 | B193: =Data!C5=0 -> TRUE
A205: operators: Data!C5+1 | B205: =Data!C5+1 -> 1
A217: operators: "1/15/2024"+0 | B217: ="1/15/2024"+0 -> 45306
A229: operators: "2024-01-15"+1 | B229: ="2024-01-15"+1 -> 45307
A241: operators: 0.1+0.2=0.3 | B241: =0.1+0.2=0.3 -> TRUE
A253: operators: 9E+307*10 | B253: =9E+307*10 -> #NUM!
A265: operators: 1/0 | B265: =1/0 -> #DIV/0!
A277: operators: Data!C2+Data!C3 | B277: =Data!C2+Data!C3 -> 3
A289: operators: Data!C2+Data!C7 | B289: =Data!C2+Data!C7 -> #VALUE!
A301: operators: "x"+1 | B301: ="x"+1 -> #VALUE!
A313: operators: 2^0.5 | B313: =2^0.5 -> 1.4142136
A325: operators: Data!A2:A3*2 | B325: {=Data!A2:A3*2} -> 10
B326: 6
A337: math: SUM(Data!A2:A11) | B337: =SUM(Data!A2:A11) -> 55
A349: math: SUM(Data!C2:C11) | B349: =SUM(Data!C2:C11) -> 7.5
A361: math: SUM("2",3,TRUE) | B361: =SUM("2",3,TRUE) -> 6
A373: math: SUM(Data!A2:A11,100) | B373: =SUM(Data!A2:A11,100) -> 155
A385: math: SUM(Data!A:A) | B385: =SUM(Data!A:A) -> 55
A397: math: SUM(Nums) | B397: =SUM(Nums) -> 55
A409: math: SUM(Data!A2:B11) | B409: =SUM(Data!A2:B11) -> 55
A421: math: ROUND(2.345,2) | B421: =ROUND(2.345,2) -> 2.35
A433: math: ROUND(-2.5,0) | B433: =ROUND(-2.5,0) -> -3
A445: math: ROUND(1234.5,-2) | B445: =ROUND(1234.5,-2) -> 1200
A457: math: ROUNDUP(2.341,2) | B457: =ROUNDUP(2.341,2) -> 2.35
...

Sheet Data
A1: Num | B1: Name | C1: Mixed | D1: Date | E1: Cat | F1: Sorted | G1: Price | H1: Qty
A2: 5 | B2: apple | C2: 1 | D2: 45292 | E2: a | F2: 10 | G2: 1.25 | H2: 3
A3: 3 | B3: Banana | C3: 2 | D3: 45329 | E3: b | F3: 20 | G3: 0.5 | H3: 12
A4: 8 | B4: cherry | C4: TRUE | D4: 45366 | E4: a | F4: 30 | G4: 4.75 | H4: 1
A5: 1 | B5: date | D5: 45403 | E5: c | F5: 40 | G5: 2 | H5: 7
A6: 9 | B6: Elder | C6: 5 | D6: 45440 | E6: b | F6: 50 | G6: 10.5 | H6: 2
A7: 2 | B7: fig | C7: x | D7: 45477 | E7: a | F7: 60 | G7: 3.3 | H7: 5
A8: 7 | B8: grape | C8: 3.5 | D8: 45514 | E8: c | F8: 70 | G8: 0.99 | H8: 20
A9: 4 | B9: honeydew | C9: FALSE | D9: 45551 | E9: a | F9: 80 | G9: 6.25 | H9: 4
A10: 6 | B10: kiwi | C10: -2 | D10: 45588 | E10: b | F10: 90 | G10: 1.1 | H10: 9
A11: 10 | B11: lemon | C11: 0 | D11: 45625 | E11: c | F11: 100 | G11: 8 | H11: 6

Sheet Other
A1: 100 | B1: far | D1: =TEXT(1234.5,"#,##0.00") -> 1,234.50
A2: 200 | B2: 3
